<robot name = "robot">
    <link name="Box0">
        <inertial>
            <origin xyz="0 0 1" rpy="0 0 0"/>
            <mass value="1" />
            <inertia ixx="100" ixy="0" ixz="0" iyy="100" iyz="0" izz="100" />
        </inertial>
        <visual>
            <origin xyz="0 0 1" rpy="0 0 0"/>
            <geometry>
                <box size="1.6324121215998166 1.454095438332755 0.7382458045793239" />
            </geometry>
            <material name="Blue">
                <color rgba="0 0 1.0 1.0"/>
            </material>
        </visual>
        <collision>
            <origin xyz="0 0 1" rpy="0 0 0"/>
            <geometry>
                <box size="1.6324121215998166 1.454095438332755 0.7382458045793239" />
            </geometry>
        </collision>
    </link>
    <joint name="Box0_Box1" type="revolute">
       <parent link="Box0"/>
       <child  link="Box1"/>
       <origin rpy="0 0 0" xyz="0 1.7098701249136659 0" />
     <axis xyz="0 0 1"/>
       <limit effort="0.0" lower="-3.14159" upper="3.14159" velocity="0.0"/>
    </joint>
    <link name="Box1">
        <inertial>
            <origin xyz="0 0 1" rpy="0 0 0"/>
            <mass value="1" />
            <inertia ixx="100" ixy="0" ixz="0" iyy="100" iyz="0" izz="100" />
        </inertial>
        <visual>
            <origin xyz="0 0 1" rpy="0 0 0"/>
            <geometry>
                <box size="1.6980373785606788 1.9656448114945768 1.7267631745953227" />
            </geometry>
            <material name="Blue">
                <color rgba="0 0 1.0 1.0"/>
            </material>
        </visual>
        <collision>
            <origin xyz="0 0 1" rpy="0 0 0"/>
            <geometry>
                <box size="1.6980373785606788 1.9656448114945768 1.7267631745953227" />
            </geometry>
        </collision>
    </link>
    <joint name="Box1_Box2" type="revolute">
       <parent link="Box1"/>
       <child  link="Box2"/>
       <origin rpy="0 0 0" xyz="0 1.5775896404694176 0" />
     <axis xyz="0 0 1"/>
       <limit effort="0.0" lower="-3.14159" upper="3.14159" velocity="0.0"/>
    </joint>
    <link name="Box2">
        <inertial>
            <origin xyz="0 0 1" rpy="0 0 0"/>
            <mass value="1" />
            <inertia ixx="100" ixy="0" ixz="0" iyy="100" iyz="0" izz="100" />
        </inertial>
        <visual>
            <origin xyz="0 0 1" rpy="0 0 0"/>
            <geometry>
                <box size="1.01542372794993 1.1895344694442587 1.7164359291671751" />
            </geometry>
            <material name="Blue">
                <color rgba="0 0 1.0 1.0"/>
            </material>
        </visual>
        <collision>
            <origin xyz="0 0 1" rpy="0 0 0"/>
            <geometry>
                <box size="1.01542372794993 1.1895344694442587 1.7164359291671751" />
            </geometry>
        </collision>
    </link>
    <joint name="Box2_Box3" type="revolute">
       <parent link="Box2"/>
       <child  link="Box3"/>
       <origin rpy="0 0 0" xyz="0 1.3106555070551429 0" />
     <axis xyz="0 0 1"/>
       <limit effort="0.0" lower="-3.14159" upper="3.14159" velocity="0.0"/>
    </joint>
    <link name="Box3">
        <inertial>
            <origin xyz="0 0 1" rpy="0 0 0"/>
            <mass value="1" />
            <inertia ixx="100" ixy="0" ixz="0" iyy="100" iyz="0" izz="100" />
        </inertial>
        <visual>
            <origin xyz="0 0 1" rpy="0 0 0"/>
            <geometry>
                <box size="1.2783748536877253 1.431776544666027 1.939179357918705" />
            </geometry>
            <material name="Blue">
                <color rgba="0 0 1.0 1.0"/>
            </material>
        </visual>
        <collision>
            <origin xyz="0 0 1" rpy="0 0 0"/>
            <geometry>
                <box size="1.2783748536877253 1.431776544666027 1.939179357918705" />
            </geometry>
        </collision>
    </link>
    <joint name="Box3_Box4" type="revolute">
       <parent link="Box3"/>
       <child  link="Box4"/>
       <origin rpy="0 0 0" xyz="0 1.3917175426628796 0" />
     <axis xyz="0 0 1"/>
       <limit effort="0.0" lower="-3.14159" upper="3.14159" velocity="0.0"/>
    </joint>
    <link name="Box4">
        <inertial>
            <origin xyz="0 0 1" rpy="0 0 0"/>
            <mass value="1" />
            <inertia ixx="100" ixy="0" ixz="0" iyy="100" iyz="0" izz="100" />
        </inertial>
        <visual>
            <origin xyz="0 0 1" rpy="0 0 0"/>
            <geometry>
                <box size="1.4524189170891917 1.3516585406597321 0.5993870106156491" />
            </geometry>
            <material name="Blue">
                <color rgba="0 0 1.0 1.0"/>
            </material>
        </visual>
        <collision>
            <origin xyz="0 0 1" rpy="0 0 0"/>
            <geometry>
                <box size="1.4524189170891917 1.3516585406597321 0.5993870106156491" />
            </geometry>
        </collision>
    </link>
    <joint name="Box4_Box5" type="revolute">
       <parent link="Box4"/>
       <child  link="Box5"/>
       <origin rpy="0 0 0" xyz="0 1.0450421540731645 0" />
     <axis xyz="0 0 1"/>
       <limit effort="0.0" lower="-3.14159" upper="3.14159" velocity="0.0"/>
    </joint>
    <link name="Box5">
        <inertial>
            <origin xyz="0 0 1" rpy="0 0 0"/>
            <mass value="1" />
            <inertia ixx="100" ixy="0" ixz="0" iyy="100" iyz="0" izz="100" />
        </inertial>
        <visual>
            <origin xyz="0 0 1" rpy="0 0 0"/>
            <geometry>
                <box size="0.6981600979350076 0.7384257674865968 0.5816391951510687" />
            </geometry>
            <material name="Blue">
                <color rgba="0 0 1.0 1.0"/>
            </material>
        </visual>
        <collision>
            <origin xyz="0 0 1" rpy="0 0 0"/>
            <geometry>
                <box size="0.6981600979350076 0.7384257674865968 0.5816391951510687" />
            </geometry>
        </collision>
    </link>
    <joint name="Box5_Box6" type="revolute">
       <parent link="Box5"/>
       <child  link="Box6"/>
       <origin rpy="0 0 0" xyz="0 0.8281363776380342 0" />
     <axis xyz="0 0 1"/>
       <limit effort="0.0" lower="-3.14159" upper="3.14159" velocity="0.0"/>
    </joint>
    <link name="Box6">
        <inertial>
            <origin xyz="0 0 1" rpy="0 0 0"/>
            <mass value="1" />
            <inertia ixx="100" ixy="0" ixz="0" iyy="100" iyz="0" izz="100" />
        </inertial>
        <visual>
            <origin xyz="0 0 1" rpy="0 0 0"/>
            <geometry>
                <box size="0.8064869469872259 0.9178469877894716 1.554420608448329" />
            </geometry>
            <material name="Green">
                <color rgba="0 1.0 0 1.0"/>
            </material>
        </visual>
        <collision>
            <origin xyz="0 0 1" rpy="0 0 0"/>
            <geometry>
                <box size="0.8064869469872259 0.9178469877894716 1.554420608448329" />
            </geometry>
        </collision>
    </link>
    <joint name="Box6_Box7" type="revolute">
       <parent link="Box6"/>
       <child  link="Box7"/>
       <origin rpy="0 0 0" xyz="0 1.4001882923318123 0" />
     <axis xyz="0 0 1"/>
       <limit effort="0.0" lower="-3.14159" upper="3.14159" velocity="0.0"/>
    </joint>
    <link name="Box7">
        <inertial>
            <origin xyz="0 0 1" rpy="0 0 0"/>
            <mass value="1" />
            <inertia ixx="100" ixy="0" ixz="0" iyy="100" iyz="0" izz="100" />
        </inertial>
        <visual>
            <origin xyz="0 0 1" rpy="0 0 0"/>
            <geometry>
                <box size="0.6319424379157972 1.882529596874153 0.5423268697388117" />
            </geometry>
            <material name="Green">
                <color rgba="0 1.0 0 1.0"/>
            </material>
        </visual>
        <collision>
            <origin xyz="0 0 1" rpy="0 0 0"/>
            <geometry>
                <box size="0.6319424379157972 1.882529596874153 0.5423268697388117" />
            </geometry>
        </collision>
    </link>
    <joint name="Box7_Box8" type="revolute">
       <parent link="Box7"/>
       <child  link="Box8"/>
       <origin rpy="0 0 0" xyz="0 1.7143268919815058 0" />
     <axis xyz="0 0 1"/>
       <limit effort="0.0" lower="-3.14159" upper="3.14159" velocity="0.0"/>
    </joint>
    <link name="Box8">
        <inertial>
            <origin xyz="0 0 1" rpy="0 0 0"/>
            <mass value="1" />
            <inertia ixx="100" ixy="0" ixz="0" iyy="100" iyz="0" izz="100" />
        </inertial>
        <visual>
            <origin xyz="0 0 1" rpy="0 0 0"/>
            <geometry>
                <box size="1.138023809030401 1.5461241870888585 0.6650199158226409" />
            </geometry>
            <material name="Green">
                <color rgba="0 1.0 0 1.0"/>
            </material>
        </visual>
        <collision>
            <origin xyz="0 0 1" rpy="0 0 0"/>
            <geometry>
                <box size="1.138023809030401 1.5461241870888585 0.6650199158226409" />
            </geometry>
        </collision>
    </link>
    <joint name="Box8_Box9" type="revolute">
       <parent link="Box8"/>
       <child  link="Box9"/>
       <origin rpy="0 0 0" xyz="0 1.2919477023773638 0" />
     <axis xyz="0 0 1"/>
       <limit effort="0.0" lower="-3.14159" upper="3.14159" velocity="0.0"/>
    </joint>
    <link name="Box9">
        <inertial>
            <origin xyz="0 0 1" rpy="0 0 0"/>
            <mass value="1" />
            <inertia ixx="100" ixy="0" ixz="0" iyy="100" iyz="0" izz="100" />
        </inertial>
        <visual>
            <origin xyz="0 0 1" rpy="0 0 0"/>
            <geometry>
                <box size="1.7489706310232032 1.037771217665869 0.8296009666933014" />
            </geometry>
            <material name="Blue">
                <color rgba="0 0 1.0 1.0"/>
            </material>
        </visual>
        <collision>
            <origin xyz="0 0 1" rpy="0 0 0"/>
            <geometry>
                <box size="1.7489706310232032 1.037771217665869 0.8296009666933014" />
            </geometry>
        </collision>
    </link>
</robot>